Workbook

Sheet Sheet1
A1: Code | B1: Name | C1: Weapon | D1: Hp | E1: Speed | F1: Healing | G1: Defend | H1: Damage | I1: BulletSpeed | J1: AtkSpeed | K1: Range | L1: Cooldown | M1: Amount | N1: Magnet | O1: Luck | P1: Growth | Q1: Curse | R1: Reroll | S1: Specificity | T1: CritRate | U1: CritDmg
A2: 1001 | B2: 하영 | C2: 사인검 | D2: 150 | E2: 5 | F2: 0 | G2: 0 | H2: 20 | I2: 0 | J2: 0.8 | K2: 1 | L2: 0 | M2: 0 | N2: 0 | O2: 0 | P2: 0 | Q2: 0 | R2: 0 | T2: 0.05 | U2: 1.5
A3: 1002 | B3: 한주원 | C3: 부적 | D3: 100 | E3: 5 | F3: 0 | G3: 0 | H3: 12 | I3: 0 | J3: 1.4 | K3: 99 | L3: 0 | M3: 0 | N3: 0 | O3: 0 | P3: 0 | Q3: 0 | R3: 0 | T3: 0.05 | U3: 1.5
A4: 1003 | B4: 박규혁 | C4: 삼지창 | D4: 170 | E4: 5 | F4: 0 | G4: 0 | H4: 25 | I4: 0 | J4: 0.6 | K4: 1 | L4: 0 | M4: 0 | N4: 0 | O4: 0 | P4: 0 | Q4: 0 | R4: 0 | T4: 0.05 | U4: 1.5
A5: 1004 | B5: 이아라 | C5: 신칼 | D5: 85 | E5: 5 | F5: 0 | G5: 0 | H5: 14 | I5: 0 | J5: 1.6 | K5: 99 | L5: 0 | M5: 0 | N5: 0 | O5: 0 | P5: 0 | Q5: 0 | R5: 0 | T5: 0.1 | U5: 1.5
A6: 1005 | B6: 최환조 | C6: 활 | D6: 75 | E6: 6 | F6: 0 | G6: 0 | H6: 18 | I6: 0 | J6: 1.75 | K6: 99 | L6: 0 | M6: 0 | N6: 0 | O6: 0 | P6: 0 | Q6: 0 | R6: 0 | T6: 0.05 | U6: 1.5
A7: 1006 | B7: 신지현 | C7: 곡도 | D7: 125 | E7: 4 | F7: 0 | G7: 0 | H7: 15 | I7: 0 | J7: 1.25 | K7: 1.5 | L7: 0 | M7: 0 | N7: 0 | O7: 0 | P7: 0 | Q7: 0 | R7: 0 | T7: 0.05 | U7: 1.5
A8: 1007 | B8: 임훈 | C8: 창 | D8: 135 | E8: 4 | F8: 0 | G8: 0 | H8: 17.5 | I8: 0 | J8: 1.1 | K8: 1.5 | L8: 0 | M8: 0 | N8: 0 | O8: 0 | P8: 0 | Q8: 0 | R8: 0 | T8: 0.05 | U8: 1.5
A9: 1008 | B9: 심여레 | C9: 부채 | D9: 80 | E9: 6 | F9: 0 | G9: 0 | H9: 10 | I9: 0 | J9: 1.85 | K9: 99 | L9: 0 | M9: 0 | N9: 0 | O9: 0 | P9: 0 | Q9: 0 | R9: 0 | T9: 0.05 | U9: 1.5

Sheet 증강
A1: 규칙
A2: 증강 슬롯 (최대 개수) | C2: 6
A3: 증강 최대 단계 | C3: 5
A4: 캐릭터 시작 레벨 | C4: 0
A5: 캐릭터 최대 레벨 | C5: 30
A6: 모든 증강을 끝까지 올리는 데 필요한 선택 수 | C6: =C2*C3 -> 30
A7: 시작 레벨에서 최대 레벨까지 레벨업 횟수 | C7: =C5-C4 -> 30
A8: 차이 (선택 수 - 레벨업 횟수, 0이면 딱 맞음) | C8: =C6-C7 -> 0
A10: Code | B10: Name | C10: Category | D10: Persist | E10: Target | F10: TargetName | G10: Stat | H10: Op | I10: Unit | J10: Lv1 | K10: Lv2 | L10: Lv3 | M10: Lv4 | N10: Lv5 | O10: Desc
A11: 3001 | B11: 최대 체력 | C11: 공통 | D11: 영구 | E11: 전체 | F11: =IF(ISNUMBER(E11),INDEX(Sheet1!$B:$B,MATCH(E11,Sheet1!$A:$A,0)),E11) -> 전체 | G11: Hp | H11: Mul | I11: % | J11: 0.1 | K11: 0.2 | L11: 0.3 | M11: 0.4 | N11: 0.5 | O11: 최대 체력 증가
A12: 3002 | B12: 이동 속도 | C12: 공통 | D12: 영구 | E12: 전체 | F12: =IF(ISNUMBER(E12),INDEX(Sheet1!$B:$B,MATCH(E12,Sheet1!$A:$A,0)),E12) -> 전체 | G12: Speed | H12: Mul | I12: % | J12: 0.05 | K12: 0.1 | L12: 0.15 | M12: 0.2 | N12: 0.25 | O12: 이동 속도 증가
A13: 3003 | B13: 체력 재생 | C13: 공통 | D13: 영구 | E13: 전체 | F13: =IF(ISNUMBER(E13),INDEX(Sheet1!$B:$B,MATCH(E13,Sheet1!$A:$A,0)),E13) -> 전체 | G13: Healing | H13: Add | I13: HP/초 | J13: 0.2 | K13: 0.4 | L13: 0.6 | M13: 0.8 | N13: 1 | O13: 초당 체력 회복
A14: 3004 | B14: 방어 | C14: 공통 | D14: 영구 | E14: 전체 | F14: =IF(ISNUMBER(E14),INDEX(Sheet1!$B:$B,MATCH(E14,Sheet1!$A:$A,0)),E14) -> 전체 | G14: Defend | H14: Add | I14: 피해 | J14: 1 | K14: 2 | L14: 3 | M14: 4 | N14: 5 | O14: 받는 피해를 고정값만큼 감소
A15: 3005 | B15: 공격력 | C15: 공통 | D15: 영구 | E15: 전체 | F15: =IF(ISNUMBER(E15),INDEX(Sheet1!$B:$B,MATCH(E15,Sheet1!$A:$A,0)),E15) -> 전체 | G15: Damage | H15: Mul | I15: % | J15: 0.1 | K15: 0.2 | L15: 0.3 | M15: 0.4 | N15: 0.5 | O15: 기본 공격 피해 증가
A16: 3006 | B16: 투사체 속도 | C16: 공통 | D16: 영구 | E16: 원거리 | F16: =IF(ISNUMBER(E16),INDEX(Sheet1!$B:$B,MATCH(E16,Sheet1!$A:$A,0)),E16) -> 원거리 | G16: BulletSpeed | H16: Add | I16: % | J16: 0.1 | K16: 0.2 | L16: 0.3 | M16: 0.4 | N16: 0.5 | O16: 투사체가 더 빨리 날아감
A17: 3007 | B17: 공격 속도 | C17: 공통 | D17: 영구 | E17: 전체 | F17: =IF(ISNUMBER(E17),INDEX(Sheet1!$B:$B,MATCH(E17,Sheet1!$A:$A,0)),E17) -> 전체 | G17: AtkSpeed | H17: Mul | I17: % | J17: 0.08 | K17: 0.16 | L17: 0.24 | M17: 0.32 | N17: 0.4 | O17: 초당 공격 횟수 증가
A18: 3008 | B18: 사거리 | C18: 공통 | D18: 영구 | E18: 근접 | F18: =IF(ISNUMBER(E18),INDEX(Sheet1!$B:$B,MATCH(E18,Sheet1!$A:$A,0)),E18) -> 근접 | G18: Range | H18: Add | I18: 칸 | J18: 0.1 | K18: 0.2 | L18: 0.3 | M18: 0.4 | N18: 0.5 | O18: 근접 공격이 닿는 거리 증가
A19: 3009 | B19: 쿨다운 감소 | C19: 공통 | D19: 영구 | E19: 전체 | F19: =IF(ISNUMBER(E19),INDEX(Sheet1!$B:$B,MATCH(E19,Sheet1!$A:$A,0)),E19) -> 전체 | G19: Cooldown | H19: Add | I19: % | J19: 0.05 | K19: 0.1 | L19: 0.15 | M19: 0.2 | N19: 0.25 | O19: 스킬 재사용 대기시간 감소
A20: 3010 | B20: 투사체 수 | C20: 공통 | D20: 영구 | E20: 전체 | F20: =IF(ISNUMBER(E20),INDEX(Sheet1!$B:$B,MATCH(E20,Sheet1!$A:$A,0)),E20) -> 전체 | G20: Amount | H20: Add | I20: 개 | J20: 1 | K20: 1 | L20: 2 | M20: 2 | N20: 3 | O20: 한 번에 나가는 공격 수 증가 (Lv2·Lv4는 공격력 +5%)
A21: 3011 | B21: 획득 범위 | C21: 공통 | D21: 영구 | E21: 전체 | F21: =IF(ISNUMBER(E21),INDEX(Sheet1!$B:$B,MATCH(E21,Sheet1!$A:$A,0)),E21) -> 전체 | G21: Magnet | H21: Add | I21: % | J21: 0.2 | K21: 0.4 | L21: 0.6 | M21: 0.8 | N21: 1 | O21: 경험치·재화를 끌어오는 범위 증가
A22: 3012 | B22: 행운 | C22: 공통 | D22: 영구 | E22: 전체 | F22: =IF(ISNUMBER(E22),INDEX(Sheet1!$B:$B,MATCH(E22,Sheet1!$A:$A,0)),E22) -> 전체 | G22: Luck | H22: Add | I22: % | J22: 0.1 | K22: 0.2 | L22: 0.3 | M22: 0.4 | N22: 0.5 | O22: 좋은 증강이 나올 확률 증가
... A27: 3017 | B27: 치명타 피해 | C27: 공통 | D27: 영구 | E27: 전체 | F27: =IF(ISNUMBER(E27),INDEX(Sheet1!$B:$B,MATCH(E27,Sheet1!$A:$A,0)),E27) -> 전체 | G27: CritDmg | H27: Add | I27: % | J27: 0.1 | K27: 0.2 | L27: 0.3 | M27: 0.4 | N27: 0.5 | O27: 치명타가 터졌을 때 피해 배율 증가
A28: 10011 | B28: 넓은 베기 | C28: 전용 | D28: 영구 | E28: 1001 | F28: =IF(ISNUMBER(E28),INDEX(Sheet1!$B:$B,MATCH(E28,Sheet1!$A:$A,0)),E28) -> 하영 | G28: Specificity | H28: Add | I28: % | J28: 0.1 | K28: 0.2 | L28: 0.3 | M28: 0.4 | N28: 0.5 | O28: 사인검 베기 각도 증가
A29: 10012 | B29: 연속 베기 | C29: 전용 | D29: 영구 | E29: 1001 | F29: =IF(ISNUMBER(E29),INDEX(Sheet1!$B:$B,MATCH(E29,Sheet1!$A:$A,0)),E29) -> 하영 | G29: Specificity | H29: Add | I29: % | J29: 0.5 | K29: 0.65 | L29: 0.8 | M29: 0.95 | N29: 1.1 | O29: 같은 방향으로 한 번 더 벤다. 값 = 추가 베기 피해
A30: 10021 | B30: 관통 부적 | C30: 전용 | D30: 영구 | E30: 1002 | F30: =IF(ISNUMBER(E30),INDEX(Sheet1!$B:$B,MATCH(E30,Sheet1!$A:$A,0)),E30) -> 한주원 | G30: Specificity | H30: Add | I30: 명 | J30: 1 | K30: 2 | L30: 3 | M30: 4 | N30: 5 | O30: 부적이 적을 뚫고 지나감
A31: 10022 | B31: 속박 부적 | C31: 전용 | D31: 영구 | E31: 1002 | F31: =IF(ISNUMBER(E31),INDEX(Sheet1!$B:$B,MATCH(E31,Sheet1!$A:$A,0)),E31) -> 한주원 | G31: Specificity | H31: Add | I31: % | J31: 0.1 | K31: 0.15 | L31: 0.2 | M31: 0.25 | N31: 0.3 | O31: 적중한 원귀 이동 속도 감소 (1초)
A32: 10031 | B32: 세 갈래 찌르기 | C32: 전용 | D32: 영구 | E32: 1003 | F32: =IF(ISNUMBER(E32),INDEX(Sheet1!$B:$B,MATCH(E32,Sheet1!$A:$A,0)),E32) -> 박규혁 | G32: Specificity | H32: Add | I32: 명 | J32: 1 | K32: 2 | L32: 3 | M32: 4 | N32: 5 | O32: 찌르기가 뒤의 적까지 관통
A33: 10032 | B33: 정예 사냥 | C33: 전용 | D33: 영구 | E33: 1003 | F33: =IF(ISNUMBER(E33),INDEX(Sheet1!$B:$B,MATCH(E33,Sheet1!$A:$A,0)),E33) -> 박규혁 | G33: Specificity | H33: Add | I33: % | J33: 0.1 | K33: 0.2 | L33: 0.3 | M33: 0.4 | N33: 0.5 | O33: 정예·보스에게 주는 피해 증가
A34: 10041 | B34: 돌아오는 신칼 | C34: 전용 | D34: 영구 | E34: 1004 | F34: =IF(ISNUMBER(E34),INDEX(Sheet1!$B:$B,MATCH(E34,Sheet1!$A:$A,0)),E34) -> 이아라 | G34: Specificity | H34: Add | I34: % | J34: 0.5 | K34: 0.6 | L34: 0.7 | M34: 0.8 | N34: 1 | O34: 던진 신칼이 돌아오며 한 번 더 타격. 값 = 왕복 피해
A35: 10042 | B35: 점괘 | C35: 전용 | D35: 영구 | E35: 1004 | F35: =IF(ISNUMBER(E35),INDEX(Sheet1!$B:$B,MATCH(E35,Sheet1!$A:$A,0)),E35) -> 이아라 | G35: CritRate | H35: Add | I35: % | J35: 0.04 | K35: 0.08 | L35: 0.12 | M35: 0.16 | N35: 0.2 | O35: 치명타 확률 증가
A36: 10051 | B36: 꿰뚫는 화살 | C36: 전용 | D36: 영구 | E36: 1005 | F36: =IF(ISNUMBER(E36),INDEX(Sheet1!$B:$B,MATCH(E36,Sheet1!$A:$A,0)),E36) -> 최환조 | G36: Specificity | H36: Add | I36: 명 | J36: 1 | K36: 2 | L36: 3 | M36: 4 | N36: 5 | O36: 화살 관통 수 증가
A37: 10052 | B37: 명궁 | C37: 전용 | D37: 영구 | E37: 1005 | F37: =IF(ISNUMBER(E37),INDEX(Sheet1!$B:$B,MATCH(E37,Sheet1!$A:$A,0)),E37) -> 최환조 | G37: Specificity | H37: Add | I37: % | J37: 0.1 | K37: 0.2 | L37: 0.3 | M37: 0.4 | N37: 0.5 | O37: 멀리 있는 적일수록 피해 증가 (최대치)
A38: 10061 | B38: 큰 휘두르기 | C38: 전용 | D38: 영구 | E38: 1006 | F38: =IF(ISNUMBER(E38),INDEX(Sheet1!$B:$B,MATCH(E38,Sheet1!$A:$A,0)),E38) -> 신지현 | G38: Specificity | H38: Add | I38: % | J38: 0.1 | K38: 0.2 | L38: 0.3 | M38: 0.4 | N38: 0.5 | O38: 곡도 공격 범위 증가
A39: 10062 | B39: 회전 베기 | C39: 전용 | D39: 영구 | E39: 1006 | F39: =IF(ISNUMBER(E39),INDEX(Sheet1!$B:$B,MATCH(E39,Sheet1!$A:$A,0)),E39) -> 신지현 | G39: Specificity | H39: Add | I39: % | J39: 1 | K39: 1.2 | L39: 1.4 | M39: 1.6 | N39: 2 | O39: 5번째 공격마다 주변 전체를 벤다. 값 = 회전 베기 피해
... A43: 10082 | B43: 거센 바람 | C43: 전용 | D43: 영구 | E43: 1008 | F43: =IF(ISNUMBER(E43),INDEX(Sheet1!$B:$B,MATCH(E43,Sheet1!$A:$A,0)),E43) -> 심여레 | G43: Specificity | H43: Add | I43: % | J43: 0.2 | K43: 0.4 | L43: 0.6 | M43: 0.8 | N43: 1 | O43: 넉백 거리 증가
A45: [읽는 법]
A46: Lv1~Lv5는 그 단계까지 올렸을 때의 누적 수치다. 예: 공격력 Lv3 = 기본 공격력 × (1 + 30%).
A47: Stat: Sheet1의 열 이름과 같다. 이름·무기를 뺀 수치만 대상이며, Specificity는 캐릭터 전용 세부 스킬이다.
A48: Op: Mul = 기본값에 곱한다(+%), Add = 그대로 더한다. Sheet1에서 기본값이 0인 스탯(Healing, Defend, BulletSpeed, Cooldown~Reroll)과 치명타(CritRate, CritDmg)는 Add로 쌓는다.
A49: CritRate = 치명타 확률, CritDmg = 치명타 피해 배율 (150% = 기본 공격의 1.5배). 기존 열 순서가 바뀌지 않도록 Sheet1 맨 뒤(T, U열)에 추가했다.
...
